
Execution Trace:
[ time 0 ] IDLE
[ time 1 ] IDLE
[ time 2 ] IDLE
[ time 3 ] JOB BEGINS by JOB 0
[ time 3 ] JOB BEGINS by JOB 1
[ time 3 ] Run JOB 0 at PRIORITY 2 [ TICKS 2 ALLOT 1 TIME 33 (of 34) ]
[ time 4 ] Run JOB 0 at PRIORITY 2 [ TICKS 1 ALLOT 1 TIME 32 (of 34) ]
[ time 5 ] Run JOB 0 at PRIORITY 2 [ TICKS 0 ALLOT 1 TIME 31 (of 34) ]
[ time 6 ] Run JOB 1 at PRIORITY 2 [ TICKS 2 ALLOT 1 TIME 1 (of 2) ]
[ time 7 ] Run JOB 1 at PRIORITY 2 [ TICKS 1 ALLOT 1 TIME 0 (of 2) ]
[ time 8 ] FINISHED JOB 1
[ time 8 ] Run JOB 0 at PRIORITY 1 [ TICKS 2 ALLOT 1 TIME 30 (of 34) ]
[ time 9 ] JOB BEGINS by JOB 2
[ time 9 ] Run JOB 2 at PRIORITY 2 [ TICKS 2 ALLOT 1 TIME 22 (of 23) ]
[ time 10 ] Run JOB 2 at PRIORITY 2 [ TICKS 1 ALLOT 1 TIME 21 (of 23) ]
[ time 11 ] Run JOB 2 at PRIORITY 2 [ TICKS 0 ALLOT 1 TIME 20 (of 23) ]
[ time 12 ] Run JOB 0 at PRIORITY 1 [ TICKS 1 ALLOT 1 TIME 29 (of 34) ]
[ time 13 ] Run JOB 0 at PRIORITY 1 [ TICKS 0 ALLOT 1 TIME 28 (of 34) ]
[ time 14 ] Run JOB 2 at PRIORITY 1 [ TICKS 2 ALLOT 1 TIME 19 (of 23) ]
[ time 15 ] Run JOB 2 at PRIORITY 1 [ TICKS 1 ALLOT 1 TIME 18 (of 23) ]
[ time 16 ] Run JOB 2 at PRIORITY 1 [ TICKS 0 ALLOT 1 TIME 17 (of 23) ]
[ time 17 ] Run JOB 0 at PRIORITY 0 [ TICKS 2 ALLOT 1 TIME 27 (of 34) ]
[ time 18 ] Run JOB 0 at PRIORITY 0 [ TICKS 1 ALLOT 1 TIME 26 (of 34) ]
[ time 19 ] Run JOB 0 at PRIORITY 0 [ TICKS 0 ALLOT 1 TIME 25 (of 34) ]
[ time 20 ] Run JOB 2 at PRIORITY 0 [ TICKS 2 ALLOT 1 TIME 16 (of 23) ]
[ time 21 ] Run JOB 2 at PRIORITY 0 [ TICKS 1 ALLOT 1 TIME 15 (of 23) ]
[ time 22 ] Run JOB 2 at PRIORITY 0 [ TICKS 0 ALLOT 1 TIME 14 (of 23) ]
[ time 23 ] Run JOB 0 at PRIORITY 0 [ TICKS 2 ALLOT 1 TIME 24 (of 34) ]
[ time 24 ] Run JOB 0 at PRIORITY 0 [ TICKS 1 ALLOT 1 TIME 23 (of 34) ]
[ time 25 ] Run JOB 0 at PRIORITY 0 [ TICKS 0 ALLOT 1 TIME 22 (of 34) ]
[ time 26 ] Run JOB 2 at PRIORITY 0 [ TICKS 2 ALLOT 1 TIME 13 (of 23) ]
[ time 27 ] Run JOB 2 at PRIORITY 0 [ TICKS 1 ALLOT 1 TIME 12 (of 23) ]
[ time 28 ] Run JOB 2 at PRIORITY 0 [ TICKS 0 ALLOT 1 TIME 11 (of 23) ]
[ time 29 ] Run JOB 0 at PRIORITY 0 [ TICKS 2 ALLOT 1 TIME 21 (of 34) ]
[ time 30 ] Run JOB 0 at PRIORITY 0 [ TICKS 1 ALLOT 1 TIME 20 (of 34) ]
[ time 31 ] Run JOB 0 at PRIORITY 0 [ TICKS 0 ALLOT 1 TIME 19 (of 34) ]
[ time 32 ] Run JOB 2 at PRIORITY 0 [ TICKS 2 ALLOT 1 TIME 10 (of 23) ]
[ time 33 ] Run JOB 2 at PRIORITY 0 [ TICKS 1 ALLOT 1 TIME 9 (of 23) ]
[ time 34 ] Run JOB 2 at PRIORITY 0 [ TICKS 0 ALLOT 1 TIME 8 (of 23) ]
[ time 35 ] Run JOB 0 at PRIORITY 0 [ TICKS 2 ALLOT 1 TIME 18 (of 34) ]
[ time 36 ] Run JOB 0 at PRIORITY 0 [ TICKS 1 ALLOT 1 TIME 17 (of 34) ]
[ time 37 ] Run JOB 0 at PRIORITY 0 [ TICKS 0 ALLOT 1 TIME 16 (of 34) ]
[ time 38 ] Run JOB 2 at PRIORITY 0 [ TICKS 2 ALLOT 1 TIME 7 (of 23) ]
[ time 39 ] Run JOB 2 at PRIORITY 0 [ TICKS 1 ALLOT 1 TIME 6 (of 23) ]
[ time 40 ] Run JOB 2 at PRIORITY 0 [ TICKS 0 ALLOT 1 TIME 5 (of 23) ]
[ time 41 ] Run JOB 0 at PRIORITY 0 [ TICKS 2 ALLOT 1 TIME 15 (of 34) ]
[ time 42 ] Run JOB 0 at PRIORITY 0 [ TICKS 1 ALLOT 1 TIME 14 (of 34) ]
[ time 43 ] Run JOB 0 at PRIORITY 0 [ TICKS 0 ALLOT 1 TIME 13 (of 34) ]
[ time 44 ] Run JOB 2 at PRIORITY 0 [ TICKS 2 ALLOT 1 TIME 4 (of 23) ]
[ time 45 ] Run JOB 2 at PRIORITY 0 [ TICKS 1 ALLOT 1 TIME 3 (of 23) ]
[ time 46 ] Run JOB 2 at PRIORITY 0 [ TICKS 0 ALLOT 1 TIME 2 (of 23) ]
[ time 47 ] Run JOB 0 at PRIORITY 0 [ TICKS 2 ALLOT 1 TIME 12 (of 34) ]
[ time 48 ] Run JOB 0 at PRIORITY 0 [ TICKS 1 ALLOT 1 TIME 11 (of 34) ]
[ time 49 ] Run JOB 0 at PRIORITY 0 [ TICKS 0 ALLOT 1 TIME 10 (of 34) ]
[ time 50 ] Run JOB 2 at PRIORITY 0 [ TICKS 2 ALLOT 1 TIME 1 (of 23) ]
[ time 51 ] Run JOB 2 at PRIORITY 0 [ TICKS 1 ALLOT 1 TIME 0 (of 23) ]
[ time 52 ] FINISHED JOB 2
[ time 52 ] Run JOB 0 at PRIORITY 0 [ TICKS 2 ALLOT 1 TIME 9 (of 34) ]
[ time 53 ] Run JOB 0 at PRIORITY 0 [ TICKS 1 ALLOT 1 TIME 8 (of 34) ]
[ time 54 ] Run JOB 0 at PRIORITY 0 [ TICKS 0 ALLOT 1 TIME 7 (of 34) ]
[ time 55 ] Run JOB 0 at PRIORITY 0 [ TICKS 2 ALLOT 1 TIME 6 (of 34) ]
[ time 56 ] Run JOB 0 at PRIORITY 0 [ TICKS 1 ALLOT 1 TIME 5 (of 34) ]
[ time 57 ] Run JOB 0 at PRIORITY 0 [ TICKS 0 ALLOT 1 TIME 4 (of 34) ]
[ time 58 ] Run JOB 0 at PRIORITY 0 [ TICKS 2 ALLOT 1 TIME 3 (of 34) ]
[ time 59 ] Run JOB 0 at PRIORITY 0 [ TICKS 1 ALLOT 1 TIME 2 (of 34) ]
[ time 60 ] Run JOB 0 at PRIORITY 0 [ TICKS 0 ALLOT 1 TIME 1 (of 34) ]
[ time 61 ] Run JOB 0 at PRIORITY 0 [ TICKS 2 ALLOT 1 TIME 0 (of 34) ]
[ time 62 ] FINISHED JOB 0
