
Execution Trace:
[ time 0 ] JOB BEGINS by JOB 0
[ time 0 ] JOB BEGINS by JOB 1
[ time 0 ] JOB BEGINS by JOB 2
[ time 0 ] Run JOB 0 at PRIORITY 2 [ TICKS 0 ALLOT 1 TIME 19 (of 20) ]
[ time 1 ] Run JOB 1 at PRIORITY 2 [ TICKS 0 ALLOT 1 TIME 29 (of 30) ]
[ time 2 ] Run JOB 2 at PRIORITY 2 [ TICKS 0 ALLOT 1 TIME 59 (of 60) ]
[ time 3 ] Run JOB 0 at PRIORITY 1 [ TICKS 0 ALLOT 1 TIME 18 (of 20) ]
[ time 4 ] Run JOB 1 at PRIORITY 1 [ TICKS 0 ALLOT 1 TIME 28 (of 30) ]
[ time 5 ] Run JOB 2 at PRIORITY 1 [ TICKS 0 ALLOT 1 TIME 58 (of 60) ]
[ time 6 ] Run JOB 0 at PRIORITY 0 [ TICKS 0 ALLOT 1 TIME 17 (of 20) ]
[ time 7 ] Run JOB 1 at PRIORITY 0 [ TICKS 0 ALLOT 1 TIME 27 (of 30) ]
[ time 8 ] Run JOB 2 at PRIORITY 0 [ TICKS 0 ALLOT 1 TIME 57 (of 60) ]
[ time 9 ] Run JOB 0 at PRIORITY 0 [ TICKS 0 ALLOT 1 TIME 16 (of 20) ]
[ time 10 ] Run JOB 1 at PRIORITY 0 [ TICKS 0 ALLOT 1 TIME 26 (of 30) ]
[ time 11 ] Run JOB 2 at PRIORITY 0 [ TICKS 0 ALLOT 1 TIME 56 (of 60) ]
[ time 12 ] Run JOB 0 at PRIORITY 0 [ TICKS 0 ALLOT 1 TIME 15 (of 20) ]
[ time 13 ] Run JOB 1 at PRIORITY 0 [ TICKS 0 ALLOT 1 TIME 25 (of 30) ]
[ time 14 ] Run JOB 2 at PRIORITY 0 [ TICKS 0 ALLOT 1 TIME 55 (of 60) ]
[ time 15 ] Run JOB 0 at PRIORITY 0 [ TICKS 0 ALLOT 1 TIME 14 (of 20) ]
[ time 16 ] Run JOB 1 at PRIORITY 0 [ TICKS 0 ALLOT 1 TIME 24 (of 30) ]
[ time 17 ] Run JOB 2 at PRIORITY 0 [ TICKS 0 ALLOT 1 TIME 54 (of 60) ]
[ time 18 ] Run JOB 0 at PRIORITY 0 [ TICKS 0 ALLOT 1 TIME 13 (of 20) ]
[ time 19 ] Run JOB 1 at PRIORITY 0 [ TICKS 0 ALLOT 1 TIME 23 (of 30) ]
[ time 20 ] Run JOB 2 at PRIORITY 0 [ TICKS 0 ALLOT 1 TIME 53 (of 60) ]
[ time 21 ] Run JOB 0 at PRIORITY 0 [ TICKS 0 ALLOT 1 TIME 12 (of 20) ]
[ time 22 ] Run JOB 1 at PRIORITY 0 [ TICKS 0 ALLOT 1 TIME 22 (of 30) ]
[ time 23 ] Run JOB 2 at PRIORITY 0 [ TICKS 0 ALLOT 1 TIME 52 (of 60) ]
[ time 24 ] Run JOB 0 at PRIORITY 0 [ TICKS 0 ALLOT 1 TIME 11 (of 20) ]
[ time 25 ] Run JOB 1 at PRIORITY 0 [ TICKS 0 ALLOT 1 TIME 21 (of 30) ]
[ time 26 ] Run JOB 2 at PRIORITY 0 [ TICKS 0 ALLOT 1 TIME 51 (of 60) ]
[ time 27 ] Run JOB 0 at PRIORITY 0 [ TICKS 0 ALLOT 1 TIME 10 (of 20) ]
[ time 28 ] Run JOB 1 at PRIORITY 0 [ TICKS 0 ALLOT 1 TIME 20 (of 30) ]
[ time 29 ] Run JOB 2 at PRIORITY 0 [ TICKS 0 ALLOT 1 TIME 50 (of 60) ]
[ time 30 ] Run JOB 0 at PRIORITY 0 [ TICKS 0 ALLOT 1 TIME 9 (of 20) ]
[ time 31 ] Run JOB 1 at PRIORITY 0 [ TICKS 0 ALLOT 1 TIME 19 (of 30) ]
[ time 32 ] Run JOB 2 at PRIORITY 0 [ TICKS 0 ALLOT 1 TIME 49 (of 60) ]
[ time 33 ] Run JOB 0 at PRIORITY 0 [ TICKS 0 ALLOT 1 TIME 8 (of 20) ]
[ time 34 ] Run JOB 1 at PRIORITY 0 [ TICKS 0 ALLOT 1 TIME 18 (of 30) ]
[ time 35 ] Run JOB 2 at PRIORITY 0 [ TICKS 0 ALLOT 1 TIME 48 (of 60) ]
[ time 36 ] Run JOB 0 at PRIORITY 0 [ TICKS 0 ALLOT 1 TIME 7 (of 20) ]
[ time 37 ] Run JOB 1 at PRIORITY 0 [ TICKS 0 ALLOT 1 TIME 17 (of 30) ]
[ time 38 ] Run JOB 2 at PRIORITY 0 [ TICKS 0 ALLOT 1 TIME 47 (of 60) ]
[ time 39 ] Run JOB 0 at PRIORITY 0 [ TICKS 0 ALLOT 1 TIME 6 (of 20) ]
[ time 40 ] Run JOB 1 at PRIORITY 0 [ TICKS 0 ALLOT 1 TIME 16 (of 30) ]
[ time 41 ] Run JOB 2 at PRIORITY 0 [ TICKS 0 ALLOT 1 TIME 46 (of 60) ]
[ time 42 ] Run JOB 0 at PRIORITY 0 [ TICKS 0 ALLOT 1 TIME 5 (of 20) ]
[ time 43 ] Run JOB 1 at PRIORITY 0 [ TICKS 0 ALLOT 1 TIME 15 (of 30) ]
[ time 44 ] Run JOB 2 at PRIORITY 0 [ TICKS 0 ALLOT 1 TIME 45 (of 60) ]
[ time 45 ] Run JOB 0 at PRIORITY 0 [ TICKS 0 ALLOT 1 TIME 4 (of 20) ]
[ time 46 ] Run JOB 1 at PRIORITY 0 [ TICKS 0 ALLOT 1 TIME 14 (of 30) ]
[ time 47 ] Run JOB 2 at PRIORITY 0 [ TICKS 0 ALLOT 1 TIME 44 (of 60) ]
[ time 48 ] Run JOB 0 at PRIORITY 0 [ TICKS 0 ALLOT 1 TIME 3 (of 20) ]
[ time 49 ] Run JOB 1 at PRIORITY 0 [ TICKS 0 ALLOT 1 TIME 13 (of 30) ]
[ time 50 ] Run JOB 2 at PRIORITY 0 [ TICKS 0 ALLOT 1 TIME 43 (of 60) ]
[ time 51 ] Run JOB 0 at PRIORITY 0 [ TICKS 0 ALLOT 1 TIME 2 (of 20) ]
[ time 52 ] Run JOB 1 at PRIORITY 0 [ TICKS 0 ALLOT 1 TIME 12 (of 30) ]
[ time 53 ] Run JOB 2 at PRIORITY 0 [ TICKS 0 ALLOT 1 TIME 42 (of 60) ]
[ time 54 ] Run JOB 0 at PRIORITY 0 [ TICKS 0 ALLOT 1 TIME 1 (of 20) ]
[ time 55 ] Run JOB 1 at PRIORITY 0 [ TICKS 0 ALLOT 1 TIME 11 (of 30) ]
[ time 56 ] Run JOB 2 at PRIORITY 0 [ TICKS 0 ALLOT 1 TIME 41 (of 60) ]
[ time 57 ] Run JOB 0 at PRIORITY 0 [ TICKS 0 ALLOT 1 TIME 0 (of 20) ]
[ time 58 ] FINISHED JOB 0
[ time 58 ] Run JOB 1 at PRIORITY 0 [ TICKS 0 ALLOT 1 TIME 10 (of 30) ]
[ time 59 ] Run JOB 2 at PRIORITY 0 [ TICKS 0 ALLOT 1 TIME 40 (of 60) ]
[ time 60 ] Run JOB 1 at PRIORITY 0 [ TICKS 0 ALLOT 1 TIME 9 (of 30) ]
[ time 61 ] Run JOB 2 at PRIORITY 0 [ TICKS 0 ALLOT 1 TIME 39 (of 60) ]
[ time 62 ] Run JOB 1 at PRIORITY 0 [ TICKS 0 ALLOT 1 TIME 8 (of 30) ]
[ time 63 ] Run JOB 2 at PRIORITY 0 [ TICKS 0 ALLOT 1 TIME 38 (of 60) ]
[ time 64 ] Run JOB 1 at PRIORITY 0 [ TICKS 0 ALLOT 1 TIME 7 (of 30) ]
[ time 65 ] Run JOB 2 at PRIORITY 0 [ TICKS 0 ALLOT 1 TIME 37 (of 60) ]
[ time 66 ] Run JOB 1 at PRIORITY 0 [ TICKS 0 ALLOT 1 TIME 6 (of 30) ]
[ time 67 ] Run JOB 2 at PRIORITY 0 [ TICKS 0 ALLOT 1 TIME 36 (of 60) ]
[ time 68 ] Run JOB 1 at PRIORITY 0 [ TICKS 0 ALLOT 1 TIME 5 (of 30) ]
[ time 69 ] Run JOB 2 at PRIORITY 0 [ TICKS 0 ALLOT 1 TIME 35 (of 60) ]
[ time 70 ] Run JOB 1 at PRIORITY 0 [ TICKS 0 ALLOT 1 TIME 4 (of 30) ]
[ time 71 ] Run JOB 2 at PRIORITY 0 [ TICKS 0 ALLOT 1 TIME 34 (of 60) ]
[ time 72 ] Run JOB 1 at PRIORITY 0 [ TICKS 0 ALLOT 1 TIME 3 (of 30) ]
[ time 73 ] Run JOB 2 at PRIORITY 0 [ TICKS 0 ALLOT 1 TIME 33 (of 60) ]
[ time 74 ] Run JOB 1 at PRIORITY 0 [ TICKS 0 ALLOT 1 TIME 2 (of 30) ]
[ time 75 ] Run JOB 2 at PRIORITY 0 [ TICKS 0 ALLOT 1 TIME 32 (of 60) ]
[ time 76 ] Run JOB 1 at PRIORITY 0 [ TICKS 0 ALLOT 1 TIME 1 (of 30) ]
[ time 77 ] Run JOB 2 at PRIORITY 0 [ TICKS 0 ALLOT 1 TIME 31 (of 60) ]
[ time 78 ] Run JOB 1 at PRIORITY 0 [ TICKS 0 ALLOT 1 TIME 0 (of 30) ]
[ time 79 ] FINISHED JOB 1
[ time 79 ] Run JOB 2 at PRIORITY 0 [ TICKS 0 ALLOT 1 TIME 30 (of 60) ]
[ time 80 ] Run JOB 2 at PRIORITY 0 [ TICKS 0 ALLOT 1 TIME 29 (of 60) ]
[ time 81 ] Run JOB 2 at PRIORITY 0 [ TICKS 0 ALLOT 1 TIME 28 (of 60) ]
[ time 82 ] Run JOB 2 at PRIORITY 0 [ TICKS 0 ALLOT 1 TIME 27 (of 60) ]
[ time 83 ] Run JOB 2 at PRIORITY 0 [ TICKS 0 ALLOT 1 TIME 26 (of 60) ]
[ time 84 ] Run JOB 2 at PRIORITY 0 [ TICKS 0 ALLOT 1 TIME 25 (of 60) ]
[ time 85 ] Run JOB 2 at PRIORITY 0 [ TICKS 0 ALLOT 1 TIME 24 (of 60) ]
[ time 86 ] Run JOB 2 at PRIORITY 0 [ TICKS 0 ALLOT 1 TIME 23 (of 60) ]
[ time 87 ] Run JOB 2 at PRIORITY 0 [ TICKS 0 ALLOT 1 TIME 22 (of 60) ]
[ time 88 ] Run JOB 2 at PRIORITY 0 [ TICKS 0 ALLOT 1 TIME 21 (of 60) ]
[ time 89 ] Run JOB 2 at PRIORITY 0 [ TICKS 0 ALLOT 1 TIME 20 (of 60) ]
[ time 90 ] Run JOB 2 at PRIORITY 0 [ TICKS 0 ALLOT 1 TIME 19 (of 60) ]
[ time 91 ] Run JOB 2 at PRIORITY 0 [ TICKS 0 ALLOT 1 TIME 18 (of 60) ]
[ time 92 ] Run JOB 2 at PRIORITY 0 [ TICKS 0 ALLOT 1 TIME 17 (of 60) ]
[ time 93 ] Run JOB 2 at PRIORITY 0 [ TICKS 0 ALLOT 1 TIME 16 (of 60) ]
[ time 94 ] Run JOB 2 at PRIORITY 0 [ TICKS 0 ALLOT 1 TIME 15 (of 60) ]
[ time 95 ] Run JOB 2 at PRIORITY 0 [ TICKS 0 ALLOT 1 TIME 14 (of 60) ]
[ time 96 ] Run JOB 2 at PRIORITY 0 [ TICKS 0 ALLOT 1 TIME 13 (of 60) ]
[ time 97 ] Run JOB 2 at PRIORITY 0 [ TICKS 0 ALLOT 1 TIME 12 (of 60) ]
[ time 98 ] Run JOB 2 at PRIORITY 0 [ TICKS 0 ALLOT 1 TIME 11 (of 60) ]
[ time 99 ] Run JOB 2 at PRIORITY 0 [ TICKS 0 ALLOT 1 TIME 10 (of 60) ]
[ time 100 ] Run JOB 2 at PRIORITY 0 [ TICKS 0 ALLOT 1 TIME 9 (of 60) ]
[ time 101 ] Run JOB 2 at PRIORITY 0 [ TICKS 0 ALLOT 1 TIME 8 (of 60) ]
[ time 102 ] Run JOB 2 at PRIORITY 0 [ TICKS 0 ALLOT 1 TIME 7 (of 60) ]
[ time 103 ] Run JOB 2 at PRIORITY 0 [ TICKS 0 ALLOT 1 TIME 6 (of 60) ]
[ time 104 ] Run JOB 2 at PRIORITY 0 [ TICKS 0 ALLOT 1 TIME 5 (of 60) ]
[ time 105 ] Run JOB 2 at PRIORITY 0 [ TICKS 0 ALLOT 1 TIME 4 (of 60) ]
[ time 106 ] Run JOB 2 at PRIORITY 0 [ TICKS 0 ALLOT 1 TIME 3 (of 60) ]
[ time 107 ] Run JOB 2 at PRIORITY 0 [ TICKS 0 ALLOT 1 TIME 2 (of 60) ]
[ time 108 ] Run JOB 2 at PRIORITY 0 [ TICKS 0 ALLOT 1 TIME 1 (of 60) ]
[ time 109 ] Run JOB 2 at PRIORITY 0 [ TICKS 0 ALLOT 1 TIME 0 (of 60) ]
[ time 110 ] FINISHED JOB 2
