
Execution Trace:
[ time 0 ] JOB BEGINS by JOB 2
[ time 0 ] Run JOB 2 at PRIORITY 1 [ TICKS 0 ALLOT 1 TIME 31 (of 32) ]
[ time 1 ] Run JOB 2 at PRIORITY 0 [ TICKS 0 ALLOT 1 TIME 30 (of 32) ]
[ time 2 ] JOB BEGINS by JOB 0
[ time 2 ] Run JOB 0 at PRIORITY 2 [ TICKS 0 ALLOT 1 TIME 0 (of 1) ]
[ time 3 ] FINISHED JOB 0
[ time 3 ] JOB BEGINS by JOB 1
[ time 3 ] Run JOB 2 at PRIORITY 0 [ TICKS 0 ALLOT 1 TIME 29 (of 32) ]
[ time 4 ] Run JOB 1 at PRIORITY 0 [ TICKS 0 ALLOT 1 TIME 44 (of 45) ]
[ time 5 ] Run JOB 2 at PRIORITY 0 [ TICKS 0 ALLOT 1 TIME 28 (of 32) ]
[ time 6 ] Run JOB 1 at PRIORITY 0 [ TICKS 0 ALLOT 1 TIME 43 (of 45) ]
[ time 7 ] Run JOB 2 at PRIORITY 0 [ TICKS 0 ALLOT 1 TIME 27 (of 32) ]
[ time 8 ] Run JOB 1 at PRIORITY 0 [ TICKS 0 ALLOT 1 TIME 42 (of 45) ]
[ time 9 ] Run JOB 2 at PRIORITY 0 [ TICKS 0 ALLOT 1 TIME 26 (of 32) ]
[ time 10 ] Run JOB 1 at PRIORITY 0 [ TICKS 0 ALLOT 1 TIME 41 (of 45) ]
[ time 11 ] Run JOB 2 at PRIORITY 0 [ TICKS 0 ALLOT 1 TIME 25 (of 32) ]
[ time 12 ] Run JOB 1 at PRIORITY 0 [ TICKS 0 ALLOT 1 TIME 40 (of 45) ]
[ time 13 ] Run JOB 2 at PRIORITY 0 [ TICKS 0 ALLOT 1 TIME 24 (of 32) ]
[ time 14 ] Run JOB 1 at PRIORITY 0 [ TICKS 0 ALLOT 1 TIME 39 (of 45) ]
[ time 15 ] Run JOB 2 at PRIORITY 0 [ TICKS 0 ALLOT 1 TIME 23 (of 32) ]
[ time 16 ] Run JOB 1 at PRIORITY 0 [ TICKS 0 ALLOT 1 TIME 38 (of 45) ]
[ time 17 ] Run JOB 2 at PRIORITY 0 [ TICKS 0 ALLOT 1 TIME 22 (of 32) ]
[ time 18 ] Run JOB 1 at PRIORITY 0 [ TICKS 0 ALLOT 1 TIME 37 (of 45) ]
[ time 19 ] Run JOB 2 at PRIORITY 0 [ TICKS 0 ALLOT 1 TIME 21 (of 32) ]
[ time 20 ] Run JOB 1 at PRIORITY 0 [ TICKS 0 ALLOT 1 TIME 36 (of 45) ]
[ time 21 ] Run JOB 2 at PRIORITY 0 [ TICKS 0 ALLOT 1 TIME 20 (of 32) ]
[ time 22 ] Run JOB 1 at PRIORITY 0 [ TICKS 0 ALLOT 1 TIME 35 (of 45) ]
[ time 23 ] Run JOB 2 at PRIORITY 0 [ TICKS 0 ALLOT 1 TIME 19 (of 32) ]
[ time 24 ] Run JOB 1 at PRIORITY 0 [ TICKS 0 ALLOT 1 TIME 34 (of 45) ]
[ time 25 ] Run JOB 2 at PRIORITY 0 [ TICKS 0 ALLOT 1 TIME 18 (of 32) ]
[ time 26 ] Run JOB 1 at PRIORITY 0 [ TICKS 0 ALLOT 1 TIME 33 (of 45) ]
[ time 27 ] Run JOB 2 at PRIORITY 0 [ TICKS 0 ALLOT 1 TIME 17 (of 32) ]
[ time 28 ] Run JOB 1 at PRIORITY 0 [ TICKS 0 ALLOT 1 TIME 32 (of 45) ]
[ time 29 ] Run JOB 2 at PRIORITY 0 [ TICKS 0 ALLOT 1 TIME 16 (of 32) ]
[ time 30 ] Run JOB 1 at PRIORITY 0 [ TICKS 0 ALLOT 1 TIME 31 (of 45) ]
[ time 31 ] Run JOB 2 at PRIORITY 0 [ TICKS 0 ALLOT 1 TIME 15 (of 32) ]
[ time 32 ] Run JOB 1 at PRIORITY 0 [ TICKS 0 ALLOT 1 TIME 30 (of 45) ]
[ time 33 ] Run JOB 2 at PRIORITY 0 [ TICKS 0 ALLOT 1 TIME 14 (of 32) ]
[ time 34 ] Run JOB 1 at PRIORITY 0 [ TICKS 0 ALLOT 1 TIME 29 (of 45) ]
[ time 35 ] Run JOB 2 at PRIORITY 0 [ TICKS 0 ALLOT 1 TIME 13 (of 32) ]
[ time 36 ] Run JOB 1 at PRIORITY 0 [ TICKS 0 ALLOT 1 TIME 28 (of 45) ]
[ time 37 ] Run JOB 2 at PRIORITY 0 [ TICKS 0 ALLOT 1 TIME 12 (of 32) ]
[ time 38 ] Run JOB 1 at PRIORITY 0 [ TICKS 0 ALLOT 1 TIME 27 (of 45) ]
[ time 39 ] Run JOB 2 at PRIORITY 0 [ TICKS 0 ALLOT 1 TIME 11 (of 32) ]
[ time 40 ] Run JOB 1 at PRIORITY 0 [ TICKS 0 ALLOT 1 TIME 26 (of 45) ]
[ time 41 ] Run JOB 2 at PRIORITY 0 [ TICKS 0 ALLOT 1 TIME 10 (of 32) ]
[ time 42 ] Run JOB 1 at PRIORITY 0 [ TICKS 0 ALLOT 1 TIME 25 (of 45) ]
[ time 43 ] Run JOB 2 at PRIORITY 0 [ TICKS 0 ALLOT 1 TIME 9 (of 32) ]
[ time 44 ] Run JOB 1 at PRIORITY 0 [ TICKS 0 ALLOT 1 TIME 24 (of 45) ]
[ time 45 ] Run JOB 2 at PRIORITY 0 [ TICKS 0 ALLOT 1 TIME 8 (of 32) ]
[ time 46 ] Run JOB 1 at PRIORITY 0 [ TICKS 0 ALLOT 1 TIME 23 (of 45) ]
[ time 47 ] Run JOB 2 at PRIORITY 0 [ TICKS 0 ALLOT 1 TIME 7 (of 32) ]
[ time 48 ] Run JOB 1 at PRIORITY 0 [ TICKS 0 ALLOT 1 TIME 22 (of 45) ]
[ time 49 ] Run JOB 2 at PRIORITY 0 [ TICKS 0 ALLOT 1 TIME 6 (of 32) ]
[ time 50 ] Run JOB 1 at PRIORITY 0 [ TICKS 0 ALLOT 1 TIME 21 (of 45) ]
[ time 51 ] Run JOB 2 at PRIORITY 0 [ TICKS 0 ALLOT 1 TIME 5 (of 32) ]
[ time 52 ] Run JOB 1 at PRIORITY 0 [ TICKS 0 ALLOT 1 TIME 20 (of 45) ]
[ time 53 ] Run JOB 2 at PRIORITY 0 [ TICKS 0 ALLOT 1 TIME 4 (of 32) ]
[ time 54 ] Run JOB 1 at PRIORITY 0 [ TICKS 0 ALLOT 1 TIME 19 (of 45) ]
[ time 55 ] Run JOB 2 at PRIORITY 0 [ TICKS 0 ALLOT 1 TIME 3 (of 32) ]
[ time 56 ] Run JOB 1 at PRIORITY 0 [ TICKS 0 ALLOT 1 TIME 18 (of 45) ]
[ time 57 ] Run JOB 2 at PRIORITY 0 [ TICKS 0 ALLOT 1 TIME 2 (of 32) ]
[ time 58 ] Run JOB 1 at PRIORITY 0 [ TICKS 0 ALLOT 1 TIME 17 (of 45) ]
[ time 59 ] Run JOB 2 at PRIORITY 0 [ TICKS 0 ALLOT 1 TIME 1 (of 32) ]
[ time 60 ] Run JOB 1 at PRIORITY 0 [ TICKS 0 ALLOT 1 TIME 16 (of 45) ]
[ time 61 ] Run JOB 2 at PRIORITY 0 [ TICKS 0 ALLOT 1 TIME 0 (of 32) ]
[ time 62 ] FINISHED JOB 2
[ time 62 ] Run JOB 1 at PRIORITY 0 [ TICKS 0 ALLOT 1 TIME 15 (of 45) ]
[ time 63 ] Run JOB 1 at PRIORITY 0 [ TICKS 0 ALLOT 1 TIME 14 (of 45) ]
[ time 64 ] Run JOB 1 at PRIORITY 0 [ TICKS 0 ALLOT 1 TIME 13 (of 45) ]
[ time 65 ] Run JOB 1 at PRIORITY 0 [ TICKS 0 ALLOT 1 TIME 12 (of 45) ]
[ time 66 ] Run JOB 1 at PRIORITY 0 [ TICKS 0 ALLOT 1 TIME 11 (of 45) ]
[ time 67 ] Run JOB 1 at PRIORITY 0 [ TICKS 0 ALLOT 1 TIME 10 (of 45) ]
[ time 68 ] Run JOB 1 at PRIORITY 0 [ TICKS 0 ALLOT 1 TIME 9 (of 45) ]
[ time 69 ] Run JOB 1 at PRIORITY 0 [ TICKS 0 ALLOT 1 TIME 8 (of 45) ]
[ time 70 ] Run JOB 1 at PRIORITY 0 [ TICKS 0 ALLOT 1 TIME 7 (of 45) ]
[ time 71 ] Run JOB 1 at PRIORITY 0 [ TICKS 0 ALLOT 1 TIME 6 (of 45) ]
[ time 72 ] Run JOB 1 at PRIORITY 0 [ TICKS 0 ALLOT 1 TIME 5 (of 45) ]
[ time 73 ] Run JOB 1 at PRIORITY 0 [ TICKS 0 ALLOT 1 TIME 4 (of 45) ]
[ time 74 ] Run JOB 1 at PRIORITY 0 [ TICKS 0 ALLOT 1 TIME 3 (of 45) ]
[ time 75 ] Run JOB 1 at PRIORITY 0 [ TICKS 0 ALLOT 1 TIME 2 (of 45) ]
[ time 76 ] Run JOB 1 at PRIORITY 0 [ TICKS 0 ALLOT 1 TIME 1 (of 45) ]
[ time 77 ] Run JOB 1 at PRIORITY 0 [ TICKS 0 ALLOT 1 TIME 0 (of 45) ]
[ time 78 ] FINISHED JOB 1
