
Execution Trace:
[ time 0 ] JOB BEGINS by JOB 0
[ time 0 ] Run JOB 0 at PRIORITY 2 [ TICKS 0 ALLOT 1 TIME 119 (of 120) ]
[ time 1 ] Run JOB 0 at PRIORITY 1 [ TICKS 0 ALLOT 1 TIME 118 (of 120) ]
[ time 2 ] Run JOB 0 at PRIORITY 0 [ TICKS 0 ALLOT 1 TIME 117 (of 120) ]
[ time 3 ] Run JOB 0 at PRIORITY 0 [ TICKS 0 ALLOT 1 TIME 116 (of 120) ]
[ time 4 ] Run JOB 0 at PRIORITY 0 [ TICKS 0 ALLOT 1 TIME 115 (of 120) ]
[ time 5 ] Run JOB 0 at PRIORITY 0 [ TICKS 0 ALLOT 1 TIME 114 (of 120) ]
[ time 6 ] Run JOB 0 at PRIORITY 0 [ TICKS 0 ALLOT 1 TIME 113 (of 120) ]
[ time 7 ] Run JOB 0 at PRIORITY 0 [ TICKS 0 ALLOT 1 TIME 112 (of 120) ]
[ time 8 ] Run JOB 0 at PRIORITY 0 [ TICKS 0 ALLOT 1 TIME 111 (of 120) ]
[ time 9 ] Run JOB 0 at PRIORITY 0 [ TICKS 0 ALLOT 1 TIME 110 (of 120) ]
[ time 10 ] Run JOB 0 at PRIORITY 0 [ TICKS 0 ALLOT 1 TIME 109 (of 120) ]
[ time 11 ] Run JOB 0 at PRIORITY 0 [ TICKS 0 ALLOT 1 TIME 108 (of 120) ]
[ time 12 ] Run JOB 0 at PRIORITY 0 [ TICKS 0 ALLOT 1 TIME 107 (of 120) ]
[ time 13 ] Run JOB 0 at PRIORITY 0 [ TICKS 0 ALLOT 1 TIME 106 (of 120) ]
[ time 14 ] Run JOB 0 at PRIORITY 0 [ TICKS 0 ALLOT 1 TIME 105 (of 120) ]
[ time 15 ] Run JOB 0 at PRIORITY 0 [ TICKS 0 ALLOT 1 TIME 104 (of 120) ]
[ time 16 ] Run JOB 0 at PRIORITY 0 [ TICKS 0 ALLOT 1 TIME 103 (of 120) ]
[ time 17 ] Run JOB 0 at PRIORITY 0 [ TICKS 0 ALLOT 1 TIME 102 (of 120) ]
[ time 18 ] Run JOB 0 at PRIORITY 0 [ TICKS 0 ALLOT 1 TIME 101 (of 120) ]
[ time 19 ] Run JOB 0 at PRIORITY 0 [ TICKS 0 ALLOT 1 TIME 100 (of 120) ]
[ time 20 ] Run JOB 0 at PRIORITY 0 [ TICKS 0 ALLOT 1 TIME 99 (of 120) ]
[ time 21 ] Run JOB 0 at PRIORITY 0 [ TICKS 0 ALLOT 1 TIME 98 (of 120) ]
[ time 22 ] Run JOB 0 at PRIORITY 0 [ TICKS 0 ALLOT 1 TIME 97 (of 120) ]
[ time 23 ] Run JOB 0 at PRIORITY 0 [ TICKS 0 ALLOT 1 TIME 96 (of 120) ]
[ time 24 ] Run JOB 0 at PRIORITY 0 [ TICKS 0 ALLOT 1 TIME 95 (of 120) ]
[ time 25 ] Run JOB 0 at PRIORITY 0 [ TICKS 0 ALLOT 1 TIME 94 (of 120) ]
[ time 26 ] Run JOB 0 at PRIORITY 0 [ TICKS 0 ALLOT 1 TIME 93 (of 120) ]
[ time 27 ] Run JOB 0 at PRIORITY 0 [ TICKS 0 ALLOT 1 TIME 92 (of 120) ]
[ time 28 ] Run JOB 0 at PRIORITY 0 [ TICKS 0 ALLOT 1 TIME 91 (of 120) ]
[ time 29 ] Run JOB 0 at PRIORITY 0 [ TICKS 0 ALLOT 1 TIME 90 (of 120) ]
[ time 30 ] Run JOB 0 at PRIORITY 0 [ TICKS 0 ALLOT 1 TIME 89 (of 120) ]
[ time 31 ] Run JOB 0 at PRIORITY 0 [ TICKS 0 ALLOT 1 TIME 88 (of 120) ]
[ time 32 ] Run JOB 0 at PRIORITY 0 [ TICKS 0 ALLOT 1 TIME 87 (of 120) ]
[ time 33 ] Run JOB 0 at PRIORITY 0 [ TICKS 0 ALLOT 1 TIME 86 (of 120) ]
[ time 34 ] Run JOB 0 at PRIORITY 0 [ TICKS 0 ALLOT 1 TIME 85 (of 120) ]
[ time 35 ] Run JOB 0 at PRIORITY 0 [ TICKS 0 ALLOT 1 TIME 84 (of 120) ]
[ time 36 ] Run JOB 0 at PRIORITY 0 [ TICKS 0 ALLOT 1 TIME 83 (of 120) ]
[ time 37 ] Run JOB 0 at PRIORITY 0 [ TICKS 0 ALLOT 1 TIME 82 (of 120) ]
[ time 38 ] Run JOB 0 at PRIORITY 0 [ TICKS 0 ALLOT 1 TIME 81 (of 120) ]
[ time 39 ] Run JOB 0 at PRIORITY 0 [ TICKS 0 ALLOT 1 TIME 80 (of 120) ]
[ time 40 ] Run JOB 0 at PRIORITY 0 [ TICKS 0 ALLOT 1 TIME 79 (of 120) ]
[ time 41 ] Run JOB 0 at PRIORITY 0 [ TICKS 0 ALLOT 1 TIME 78 (of 120) ]
[ time 42 ] Run JOB 0 at PRIORITY 0 [ TICKS 0 ALLOT 1 TIME 77 (of 120) ]
[ time 43 ] Run JOB 0 at PRIORITY 0 [ TICKS 0 ALLOT 1 TIME 76 (of 120) ]
[ time 44 ] Run JOB 0 at PRIORITY 0 [ TICKS 0 ALLOT 1 TIME 75 (of 120) ]
[ time 45 ] Run JOB 0 at PRIORITY 0 [ TICKS 0 ALLOT 1 TIME 74 (of 120) ]
[ time 46 ] Run JOB 0 at PRIORITY 0 [ TICKS 0 ALLOT 1 TIME 73 (of 120) ]
[ time 47 ] Run JOB 0 at PRIORITY 0 [ TICKS 0 ALLOT 1 TIME 72 (of 120) ]
[ time 48 ] Run JOB 0 at PRIORITY 0 [ TICKS 0 ALLOT 1 TIME 71 (of 120) ]
[ time 49 ] Run JOB 0 at PRIORITY 0 [ TICKS 0 ALLOT 1 TIME 70 (of 120) ]
[ time 50 ] Run JOB 0 at PRIORITY 0 [ TICKS 0 ALLOT 1 TIME 69 (of 120) ]
[ time 51 ] Run JOB 0 at PRIORITY 0 [ TICKS 0 ALLOT 1 TIME 68 (of 120) ]
[ time 52 ] Run JOB 0 at PRIORITY 0 [ TICKS 0 ALLOT 1 TIME 67 (of 120) ]
[ time 53 ] Run JOB 0 at PRIORITY 0 [ TICKS 0 ALLOT 1 TIME 66 (of 120) ]
[ time 54 ] Run JOB 0 at PRIORITY 0 [ TICKS 0 ALLOT 1 TIME 65 (of 120) ]
[ time 55 ] Run JOB 0 at PRIORITY 0 [ TICKS 0 ALLOT 1 TIME 64 (of 120) ]
[ time 56 ] Run JOB 0 at PRIORITY 0 [ TICKS 0 ALLOT 1 TIME 63 (of 120) ]
[ time 57 ] Run JOB 0 at PRIORITY 0 [ TICKS 0 ALLOT 1 TIME 62 (of 120) ]
[ time 58 ] Run JOB 0 at PRIORITY 0 [ TICKS 0 ALLOT 1 TIME 61 (of 120) ]
[ time 59 ] Run JOB 0 at PRIORITY 0 [ TICKS 0 ALLOT 1 TIME 60 (of 120) ]
[ time 60 ] Run JOB 0 at PRIORITY 0 [ TICKS 0 ALLOT 1 TIME 59 (of 120) ]
[ time 61 ] Run JOB 0 at PRIORITY 0 [ TICKS 0 ALLOT 1 TIME 58 (of 120) ]
[ time 62 ] Run JOB 0 at PRIORITY 0 [ TICKS 0 ALLOT 1 TIME 57 (of 120) ]
[ time 63 ] Run JOB 0 at PRIORITY 0 [ TICKS 0 ALLOT 1 TIME 56 (of 120) ]
[ time 64 ] Run JOB 0 at PRIORITY 0 [ TICKS 0 ALLOT 1 TIME 55 (of 120) ]
[ time 65 ] Run JOB 0 at PRIORITY 0 [ TICKS 0 ALLOT 1 TIME 54 (of 120) ]
[ time 66 ] Run JOB 0 at PRIORITY 0 [ TICKS 0 ALLOT 1 TIME 53 (of 120) ]
[ time 67 ] Run JOB 0 at PRIORITY 0 [ TICKS 0 ALLOT 1 TIME 52 (of 120) ]
[ time 68 ] Run JOB 0 at PRIORITY 0 [ TICKS 0 ALLOT 1 TIME 51 (of 120) ]
[ time 69 ] Run JOB 0 at PRIORITY 0 [ TICKS 0 ALLOT 1 TIME 50 (of 120) ]
[ time 70 ] Run JOB 0 at PRIORITY 0 [ TICKS 0 ALLOT 1 TIME 49 (of 120) ]
[ time 71 ] Run JOB 0 at PRIORITY 0 [ TICKS 0 ALLOT 1 TIME 48 (of 120) ]
[ time 72 ] Run JOB 0 at PRIORITY 0 [ TICKS 0 ALLOT 1 TIME 47 (of 120) ]
[ time 73 ] Run JOB 0 at PRIORITY 0 [ TICKS 0 ALLOT 1 TIME 46 (of 120) ]
[ time 74 ] Run JOB 0 at PRIORITY 0 [ TICKS 0 ALLOT 1 TIME 45 (of 120) ]
[ time 75 ] Run JOB 0 at PRIORITY 0 [ TICKS 0 ALLOT 1 TIME 44 (of 120) ]
[ time 76 ] Run JOB 0 at PRIORITY 0 [ TICKS 0 ALLOT 1 TIME 43 (of 120) ]
[ time 77 ] Run JOB 0 at PRIORITY 0 [ TICKS 0 ALLOT 1 TIME 42 (of 120) ]
[ time 78 ] Run JOB 0 at PRIORITY 0 [ TICKS 0 ALLOT 1 TIME 41 (of 120) ]
[ time 79 ] Run JOB 0 at PRIORITY 0 [ TICKS 0 ALLOT 1 TIME 40 (of 120) ]
[ time 80 ] Run JOB 0 at PRIORITY 0 [ TICKS 0 ALLOT 1 TIME 39 (of 120) ]
[ time 81 ] Run JOB 0 at PRIORITY 0 [ TICKS 0 ALLOT 1 TIME 38 (of 120) ]
[ time 82 ] Run JOB 0 at PRIORITY 0 [ TICKS 0 ALLOT 1 TIME 37 (of 120) ]
[ time 83 ] Run JOB 0 at PRIORITY 0 [ TICKS 0 ALLOT 1 TIME 36 (of 120) ]
[ time 84 ] Run JOB 0 at PRIORITY 0 [ TICKS 0 ALLOT 1 TIME 35 (of 120) ]
[ time 85 ] Run JOB 0 at PRIORITY 0 [ TICKS 0 ALLOT 1 TIME 34 (of 120) ]
[ time 86 ] Run JOB 0 at PRIORITY 0 [ TICKS 0 ALLOT 1 TIME 33 (of 120) ]
[ time 87 ] Run JOB 0 at PRIORITY 0 [ TICKS 0 ALLOT 1 TIME 32 (of 120) ]
[ time 88 ] Run JOB 0 at PRIORITY 0 [ TICKS 0 ALLOT 1 TIME 31 (of 120) ]
[ time 89 ] Run JOB 0 at PRIORITY 0 [ TICKS 0 ALLOT 1 TIME 30 (of 120) ]
[ time 90 ] Run JOB 0 at PRIORITY 0 [ TICKS 0 ALLOT 1 TIME 29 (of 120) ]
[ time 91 ] Run JOB 0 at PRIORITY 0 [ TICKS 0 ALLOT 1 TIME 28 (of 120) ]
[ time 92 ] Run JOB 0 at PRIORITY 0 [ TICKS 0 ALLOT 1 TIME 27 (of 120) ]
[ time 93 ] Run JOB 0 at PRIORITY 0 [ TICKS 0 ALLOT 1 TIME 26 (of 120) ]
[ time 94 ] Run JOB 0 at PRIORITY 0 [ TICKS 0 ALLOT 1 TIME 25 (of 120) ]
[ time 95 ] Run JOB 0 at PRIORITY 0 [ TICKS 0 ALLOT 1 TIME 24 (of 120) ]
[ time 96 ] Run JOB 0 at PRIORITY 0 [ TICKS 0 ALLOT 1 TIME 23 (of 120) ]
[ time 97 ] Run JOB 0 at PRIORITY 0 [ TICKS 0 ALLOT 1 TIME 22 (of 120) ]
[ time 98 ] Run JOB 0 at PRIORITY 0 [ TICKS 0 ALLOT 1 TIME 21 (of 120) ]
[ time 99 ] Run JOB 0 at PRIORITY 0 [ TICKS 0 ALLOT 1 TIME 20 (of 120) ]
[ time 100 ] Run JOB 0 at PRIORITY 0 [ TICKS 0 ALLOT 1 TIME 19 (of 120) ]
[ time 101 ] Run JOB 0 at PRIORITY 0 [ TICKS 0 ALLOT 1 TIME 18 (of 120) ]
[ time 102 ] Run JOB 0 at PRIORITY 0 [ TICKS 0 ALLOT 1 TIME 17 (of 120) ]
[ time 103 ] Run JOB 0 at PRIORITY 0 [ TICKS 0 ALLOT 1 TIME 16 (of 120) ]
[ time 104 ] Run JOB 0 at PRIORITY 0 [ TICKS 0 ALLOT 1 TIME 15 (of 120) ]
[ time 105 ] Run JOB 0 at PRIORITY 0 [ TICKS 0 ALLOT 1 TIME 14 (of 120) ]
[ time 106 ] Run JOB 0 at PRIORITY 0 [ TICKS 0 ALLOT 1 TIME 13 (of 120) ]
[ time 107 ] Run JOB 0 at PRIORITY 0 [ TICKS 0 ALLOT 1 TIME 12 (of 120) ]
[ time 108 ] Run JOB 0 at PRIORITY 0 [ TICKS 0 ALLOT 1 TIME 11 (of 120) ]
[ time 109 ] Run JOB 0 at PRIORITY 0 [ TICKS 0 ALLOT 1 TIME 10 (of 120) ]
[ time 110 ] Run JOB 0 at PRIORITY 0 [ TICKS 0 ALLOT 1 TIME 9 (of 120) ]
[ time 111 ] Run JOB 0 at PRIORITY 0 [ TICKS 0 ALLOT 1 TIME 8 (of 120) ]
[ time 112 ] Run JOB 0 at PRIORITY 0 [ TICKS 0 ALLOT 1 TIME 7 (of 120) ]
[ time 113 ] Run JOB 0 at PRIORITY 0 [ TICKS 0 ALLOT 1 TIME 6 (of 120) ]
[ time 114 ] Run JOB 0 at PRIORITY 0 [ TICKS 0 ALLOT 1 TIME 5 (of 120) ]
[ time 115 ] Run JOB 0 at PRIORITY 0 [ TICKS 0 ALLOT 1 TIME 4 (of 120) ]
[ time 116 ] Run JOB 0 at PRIORITY 0 [ TICKS 0 ALLOT 1 TIME 3 (of 120) ]
[ time 117 ] Run JOB 0 at PRIORITY 0 [ TICKS 0 ALLOT 1 TIME 2 (of 120) ]
[ time 118 ] Run JOB 0 at PRIORITY 0 [ TICKS 0 ALLOT 1 TIME 1 (of 120) ]
[ time 119 ] Run JOB 0 at PRIORITY 0 [ TICKS 0 ALLOT 1 TIME 0 (of 120) ]
[ time 120 ] FINISHED JOB 0
