
Execution Trace:
[ time 0 ] IDLE
[ time 1 ] IDLE
[ time 2 ] IDLE
[ time 3 ] IDLE
[ time 4 ] JOB BEGINS by JOB 0
[ time 4 ] Run JOB 0 at PRIORITY 2 [ TICKS 2 ALLOT 1 TIME 55 (of 56) ]
[ time 5 ] JOB BEGINS by JOB 1
[ time 5 ] Run JOB 0 at PRIORITY 2 [ TICKS 1 ALLOT 1 TIME 54 (of 56) ]
[ time 6 ] Run JOB 0 at PRIORITY 2 [ TICKS 0 ALLOT 1 TIME 53 (of 56) ]
[ time 7 ] JOB BEGINS by JOB 2
[ time 7 ] Run JOB 2 at PRIORITY 2 [ TICKS 2 ALLOT 1 TIME 42 (of 43) ]
[ time 8 ] Run JOB 2 at PRIORITY 2 [ TICKS 1 ALLOT 1 TIME 41 (of 43) ]
[ time 9 ] Run JOB 2 at PRIORITY 2 [ TICKS 0 ALLOT 1 TIME 40 (of 43) ]
[ time 10 ] Run JOB 1 at PRIORITY 1 [ TICKS 2 ALLOT 1 TIME 44 (of 45) ]
[ time 11 ] Run JOB 1 at PRIORITY 1 [ TICKS 1 ALLOT 1 TIME 43 (of 45) ]
[ time 12 ] Run JOB 1 at PRIORITY 1 [ TICKS 0 ALLOT 1 TIME 42 (of 45) ]
[ time 13 ] Run JOB 0 at PRIORITY 1 [ TICKS 2 ALLOT 1 TIME 52 (of 56) ]
[ time 14 ] Run JOB 0 at PRIORITY 1 [ TICKS 1 ALLOT 1 TIME 51 (of 56) ]
[ time 15 ] Run JOB 0 at PRIORITY 1 [ TICKS 0 ALLOT 1 TIME 50 (of 56) ]
[ time 16 ] Run JOB 2 at PRIORITY 1 [ TICKS 2 ALLOT 1 TIME 39 (of 43) ]
[ time 17 ] Run JOB 2 at PRIORITY 1 [ TICKS 1 ALLOT 1 TIME 38 (of 43) ]
[ time 18 ] Run JOB 2 at PRIORITY 1 [ TICKS 0 ALLOT 1 TIME 37 (of 43) ]
[ time 19 ] Run JOB 1 at PRIORITY 0 [ TICKS 2 ALLOT 1 TIME 41 (of 45) ]
[ time 20 ] Run JOB 1 at PRIORITY 0 [ TICKS 1 ALLOT 1 TIME 40 (of 45) ]
[ time 21 ] Run JOB 1 at PRIORITY 0 [ TICKS 0 ALLOT 1 TIME 39 (of 45) ]
[ time 22 ] Run JOB 0 at PRIORITY 0 [ TICKS 2 ALLOT 1 TIME 49 (of 56) ]
[ time 23 ] Run JOB 0 at PRIORITY 0 [ TICKS 1 ALLOT 1 TIME 48 (of 56) ]
[ time 24 ] Run JOB 0 at PRIORITY 0 [ TICKS 0 ALLOT 1 TIME 47 (of 56) ]
[ time 25 ] Run JOB 2 at PRIORITY 0 [ TICKS 2 ALLOT 1 TIME 36 (of 43) ]
[ time 26 ] Run JOB 2 at PRIORITY 0 [ TICKS 1 ALLOT 1 TIME 35 (of 43) ]
[ time 27 ] Run JOB 2 at PRIORITY 0 [ TICKS 0 ALLOT 1 TIME 34 (of 43) ]
[ time 28 ] Run JOB 1 at PRIORITY 0 [ TICKS 2 ALLOT 1 TIME 38 (of 45) ]
[ time 29 ] Run JOB 1 at PRIORITY 0 [ TICKS 1 ALLOT 1 TIME 37 (of 45) ]
[ time 30 ] Run JOB 1 at PRIORITY 0 [ TICKS 0 ALLOT 1 TIME 36 (of 45) ]
[ time 31 ] Run JOB 0 at PRIORITY 0 [ TICKS 2 ALLOT 1 TIME 46 (of 56) ]
[ time 32 ] Run JOB 0 at PRIORITY 0 [ TICKS 1 ALLOT 1 TIME 45 (of 56) ]
[ time 33 ] Run JOB 0 at PRIORITY 0 [ TICKS 0 ALLOT 1 TIME 44 (of 56) ]
[ time 34 ] Run JOB 2 at PRIORITY 0 [ TICKS 2 ALLOT 1 TIME 33 (of 43) ]
[ time 35 ] Run JOB 2 at PRIORITY 0 [ TICKS 1 ALLOT 1 TIME 32 (of 43) ]
[ time 36 ] Run JOB 2 at PRIORITY 0 [ TICKS 0 ALLOT 1 TIME 31 (of 43) ]
[ time 37 ] Run JOB 1 at PRIORITY 0 [ TICKS 2 ALLOT 1 TIME 35 (of 45) ]
[ time 38 ] Run JOB 1 at PRIORITY 0 [ TICKS 1 ALLOT 1 TIME 34 (of 45) ]
[ time 39 ] Run JOB 1 at PRIORITY 0 [ TICKS 0 ALLOT 1 TIME 33 (of 45) ]
[ time 40 ] Run JOB 0 at PRIORITY 0 [ TICKS 2 ALLOT 1 TIME 43 (of 56) ]
[ time 41 ] Run JOB 0 at PRIORITY 0 [ TICKS 1 ALLOT 1 TIME 42 (of 56) ]
[ time 42 ] Run JOB 0 at PRIORITY 0 [ TICKS 0 ALLOT 1 TIME 41 (of 56) ]
[ time 43 ] Run JOB 2 at PRIORITY 0 [ TICKS 2 ALLOT 1 TIME 30 (of 43) ]
[ time 44 ] Run JOB 2 at PRIORITY 0 [ TICKS 1 ALLOT 1 TIME 29 (of 43) ]
[ time 45 ] Run JOB 2 at PRIORITY 0 [ TICKS 0 ALLOT 1 TIME 28 (of 43) ]
[ time 46 ] Run JOB 1 at PRIORITY 0 [ TICKS 2 ALLOT 1 TIME 32 (of 45) ]
[ time 47 ] Run JOB 1 at PRIORITY 0 [ TICKS 1 ALLOT 1 TIME 31 (of 45) ]
[ time 48 ] Run JOB 1 at PRIORITY 0 [ TICKS 0 ALLOT 1 TIME 30 (of 45) ]
[ time 49 ] Run JOB 0 at PRIORITY 0 [ TICKS 2 ALLOT 1 TIME 40 (of 56) ]
[ time 50 ] Run JOB 0 at PRIORITY 0 [ TICKS 1 ALLOT 1 TIME 39 (of 56) ]
[ time 51 ] Run JOB 0 at PRIORITY 0 [ TICKS 0 ALLOT 1 TIME 38 (of 56) ]
[ time 52 ] Run JOB 2 at PRIORITY 0 [ TICKS 2 ALLOT 1 TIME 27 (of 43) ]
[ time 53 ] Run JOB 2 at PRIORITY 0 [ TICKS 1 ALLOT 1 TIME 26 (of 43) ]
[ time 54 ] Run JOB 2 at PRIORITY 0 [ TICKS 0 ALLOT 1 TIME 25 (of 43) ]
[ time 55 ] Run JOB 1 at PRIORITY 0 [ TICKS 2 ALLOT 1 TIME 29 (of 45) ]
[ time 56 ] Run JOB 1 at PRIORITY 0 [ TICKS 1 ALLOT 1 TIME 28 (of 45) ]
[ time 57 ] Run JOB 1 at PRIORITY 0 [ TICKS 0 ALLOT 1 TIME 27 (of 45) ]
[ time 58 ] Run JOB 0 at PRIORITY 0 [ TICKS 2 ALLOT 1 TIME 37 (of 56) ]
[ time 59 ] Run JOB 0 at PRIORITY 0 [ TICKS 1 ALLOT 1 TIME 36 (of 56) ]
[ time 60 ] Run JOB 0 at PRIORITY 0 [ TICKS 0 ALLOT 1 TIME 35 (of 56) ]
[ time 61 ] Run JOB 2 at PRIORITY 0 [ TICKS 2 ALLOT 1 TIME 24 (of 43) ]
[ time 62 ] Run JOB 2 at PRIORITY 0 [ TICKS 1 ALLOT 1 TIME 23 (of 43) ]
[ time 63 ] Run JOB 2 at PRIORITY 0 [ TICKS 0 ALLOT 1 TIME 22 (of 43) ]
[ time 64 ] Run JOB 1 at PRIORITY 0 [ TICKS 2 ALLOT 1 TIME 26 (of 45) ]
[ time 65 ] Run JOB 1 at PRIORITY 0 [ TICKS 1 ALLOT 1 TIME 25 (of 45) ]
[ time 66 ] Run JOB 1 at PRIORITY 0 [ TICKS 0 ALLOT 1 TIME 24 (of 45) ]
[ time 67 ] Run JOB 0 at PRIORITY 0 [ TICKS 2 ALLOT 1 TIME 34 (of 56) ]
[ time 68 ] Run JOB 0 at PRIORITY 0 [ TICKS 1 ALLOT 1 TIME 33 (of 56) ]
[ time 69 ] Run JOB 0 at PRIORITY 0 [ TICKS 0 ALLOT 1 TIME 32 (of 56) ]
[ time 70 ] Run JOB 2 at PRIORITY 0 [ TICKS 2 ALLOT 1 TIME 21 (of 43) ]
[ time 71 ] Run JOB 2 at PRIORITY 0 [ TICKS 1 ALLOT 1 TIME 20 (of 43) ]
[ time 72 ] Run JOB 2 at PRIORITY 0 [ TICKS 0 ALLOT 1 TIME 19 (of 43) ]
[ time 73 ] Run JOB 1 at PRIORITY 0 [ TICKS 2 ALLOT 1 TIME 23 (of 45) ]
[ time 74 ] Run JOB 1 at PRIORITY 0 [ TICKS 1 ALLOT 1 TIME 22 (of 45) ]
[ time 75 ] Run JOB 1 at PRIORITY 0 [ TICKS 0 ALLOT 1 TIME 21 (of 45) ]
[ time 76 ] Run JOB 0 at PRIORITY 0 [ TICKS 2 ALLOT 1 TIME 31 (of 56) ]
[ time 77 ] Run JOB 0 at PRIORITY 0 [ TICKS 1 ALLOT 1 TIME 30 (of 56) ]
[ time 78 ] Run JOB 0 at PRIORITY 0 [ TICKS 0 ALLOT 1 TIME 29 (of 56) ]
[ time 79 ] Run JOB 2 at PRIORITY 0 [ TICKS 2 ALLOT 1 TIME 18 (of 43) ]
[ time 80 ] Run JOB 2 at PRIORITY 0 [ TICKS 1 ALLOT 1 TIME 17 (of 43) ]
[ time 81 ] Run JOB 2 at PRIORITY 0 [ TICKS 0 ALLOT 1 TIME 16 (of 43) ]
[ time 82 ] Run JOB 1 at PRIORITY 0 [ TICKS 2 ALLOT 1 TIME 20 (of 45) ]
[ time 83 ] Run JOB 1 at PRIORITY 0 [ TICKS 1 ALLOT 1 TIME 19 (of 45) ]
[ time 84 ] Run JOB 1 at PRIORITY 0 [ TICKS 0 ALLOT 1 TIME 18 (of 45) ]
[ time 85 ] Run JOB 0 at PRIORITY 0 [ TICKS 2 ALLOT 1 TIME 28 (of 56) ]
[ time 86 ] Run JOB 0 at PRIORITY 0 [ TICKS 1 ALLOT 1 TIME 27 (of 56) ]
[ time 87 ] Run JOB 0 at PRIORITY 0 [ TICKS 0 ALLOT 1 TIME 26 (of 56) ]
[ time 88 ] Run JOB 2 at PRIORITY 0 [ TICKS 2 ALLOT 1 TIME 15 (of 43) ]
[ time 89 ] Run JOB 2 at PRIORITY 0 [ TICKS 1 ALLOT 1 TIME 14 (of 43) ]
[ time 90 ] Run JOB 2 at PRIORITY 0 [ TICKS 0 ALLOT 1 TIME 13 (of 43) ]
[ time 91 ] Run JOB 1 at PRIORITY 0 [ TICKS 2 ALLOT 1 TIME 17 (of 45) ]
[ time 92 ] Run JOB 1 at PRIORITY 0 [ TICKS 1 ALLOT 1 TIME 16 (of 45) ]
[ time 93 ] Run JOB 1 at PRIORITY 0 [ TICKS 0 ALLOT 1 TIME 15 (of 45) ]
[ time 94 ] Run JOB 0 at PRIORITY 0 [ TICKS 2 ALLOT 1 TIME 25 (of 56) ]
[ time 95 ] Run JOB 0 at PRIORITY 0 [ TICKS 1 ALLOT 1 TIME 24 (of 56) ]
[ time 96 ] Run JOB 0 at PRIORITY 0 [ TICKS 0 ALLOT 1 TIME 23 (of 56) ]
[ time 97 ] Run JOB 2 at PRIORITY 0 [ TICKS 2 ALLOT 1 TIME 12 (of 43) ]
[ time 98 ] Run JOB 2 at PRIORITY 0 [ TICKS 1 ALLOT 1 TIME 11 (of 43) ]
[ time 99 ] Run JOB 2 at PRIORITY 0 [ TICKS 0 ALLOT 1 TIME 10 (of 43) ]
[ time 100 ] Run JOB 1 at PRIORITY 0 [ TICKS 2 ALLOT 1 TIME 14 (of 45) ]
[ time 101 ] Run JOB 1 at PRIORITY 0 [ TICKS 1 ALLOT 1 TIME 13 (of 45) ]
[ time 102 ] Run JOB 1 at PRIORITY 0 [ TICKS 0 ALLOT 1 TIME 12 (of 45) ]
[ time 103 ] Run JOB 0 at PRIORITY 0 [ TICKS 2 ALLOT 1 TIME 22 (of 56) ]
[ time 104 ] Run JOB 0 at PRIORITY 0 [ TICKS 1 ALLOT 1 TIME 21 (of 56) ]
[ time 105 ] Run JOB 0 at PRIORITY 0 [ TICKS 0 ALLOT 1 TIME 20 (of 56) ]
[ time 106 ] Run JOB 2 at PRIORITY 0 [ TICKS 2 ALLOT 1 TIME 9 (of 43) ]
[ time 107 ] Run JOB 2 at PRIORITY 0 [ TICKS 1 ALLOT 1 TIME 8 (of 43) ]
[ time 108 ] Run JOB 2 at PRIORITY 0 [ TICKS 0 ALLOT 1 TIME 7 (of 43) ]
[ time 109 ] Run JOB 1 at PRIORITY 0 [ TICKS 2 ALLOT 1 TIME 11 (of 45) ]
[ time 110 ] Run JOB 1 at PRIORITY 0 [ TICKS 1 ALLOT 1 TIME 10 (of 45) ]
[ time 111 ] Run JOB 1 at PRIORITY 0 [ TICKS 0 ALLOT 1 TIME 9 (of 45) ]
[ time 112 ] Run JOB 0 at PRIORITY 0 [ TICKS 2 ALLOT 1 TIME 19 (of 56) ]
[ time 113 ] Run JOB 0 at PRIORITY 0 [ TICKS 1 ALLOT 1 TIME 18 (of 56) ]
[ time 114 ] Run JOB 0 at PRIORITY 0 [ TICKS 0 ALLOT 1 TIME 17 (of 56) ]
[ time 115 ] Run JOB 2 at PRIORITY 0 [ TICKS 2 ALLOT 1 TIME 6 (of 43) ]
[ time 116 ] Run JOB 2 at PRIORITY 0 [ TICKS 1 ALLOT 1 TIME 5 (of 43) ]
[ time 117 ] Run JOB 2 at PRIORITY 0 [ TICKS 0 ALLOT 1 TIME 4 (of 43) ]
[ time 118 ] Run JOB 1 at PRIORITY 0 [ TICKS 2 ALLOT 1 TIME 8 (of 45) ]
[ time 119 ] Run JOB 1 at PRIORITY 0 [ TICKS 1 ALLOT 1 TIME 7 (of 45) ]
[ time 120 ] Run JOB 1 at PRIORITY 0 [ TICKS 0 ALLOT 1 TIME 6 (of 45) ]
[ time 121 ] Run JOB 0 at PRIORITY 0 [ TICKS 2 ALLOT 1 TIME 16 (of 56) ]
[ time 122 ] Run JOB 0 at PRIORITY 0 [ TICKS 1 ALLOT 1 TIME 15 (of 56) ]
[ time 123 ] Run JOB 0 at PRIORITY 0 [ TICKS 0 ALLOT 1 TIME 14 (of 56) ]
[ time 124 ] Run JOB 2 at PRIORITY 0 [ TICKS 2 ALLOT 1 TIME 3 (of 43) ]
[ time 125 ] Run JOB 2 at PRIORITY 0 [ TICKS 1 ALLOT 1 TIME 2 (of 43) ]
[ time 126 ] Run JOB 2 at PRIORITY 0 [ TICKS 0 ALLOT 1 TIME 1 (of 43) ]
[ time 127 ] Run JOB 1 at PRIORITY 0 [ TICKS 2 ALLOT 1 TIME 5 (of 45) ]
[ time 128 ] Run JOB 1 at PRIORITY 0 [ TICKS 1 ALLOT 1 TIME 4 (of 45) ]
[ time 129 ] Run JOB 1 at PRIORITY 0 [ TICKS 0 ALLOT 1 TIME 3 (of 45) ]
[ time 130 ] Run JOB 0 at PRIORITY 0 [ TICKS 2 ALLOT 1 TIME 13 (of 56) ]
[ time 131 ] Run JOB 0 at PRIORITY 0 [ TICKS 1 ALLOT 1 TIME 12 (of 56) ]
[ time 132 ] Run JOB 0 at PRIORITY 0 [ TICKS 0 ALLOT 1 TIME 11 (of 56) ]
[ time 133 ] Run JOB 2 at PRIORITY 0 [ TICKS 2 ALLOT 1 TIME 0 (of 43) ]
[ time 134 ] FINISHED JOB 2
[ time 134 ] Run JOB 1 at PRIORITY 0 [ TICKS 2 ALLOT 1 TIME 2 (of 45) ]
[ time 135 ] Run JOB 1 at PRIORITY 0 [ TICKS 1 ALLOT 1 TIME 1 (of 45) ]
[ time 136 ] Run JOB 1 at PRIORITY 0 [ TICKS 0 ALLOT 1 TIME 0 (of 45) ]
[ time 137 ] FINISHED JOB 1
[ time 137 ] Run JOB 0 at PRIORITY 0 [ TICKS 2 ALLOT 1 TIME 10 (of 56) ]
[ time 138 ] Run JOB 0 at PRIORITY 0 [ TICKS 1 ALLOT 1 TIME 9 (of 56) ]
[ time 139 ] Run JOB 0 at PRIORITY 0 [ TICKS 0 ALLOT 1 TIME 8 (of 56) ]
[ time 140 ] Run JOB 0 at PRIORITY 0 [ TICKS 2 ALLOT 1 TIME 7 (of 56) ]
[ time 141 ] Run JOB 0 at PRIORITY 0 [ TICKS 1 ALLOT 1 TIME 6 (of 56) ]
[ time 142 ] Run JOB 0 at PRIORITY 0 [ TICKS 0 ALLOT 1 TIME 5 (of 56) ]
[ time 143 ] Run JOB 0 at PRIORITY 0 [ TICKS 2 ALLOT 1 TIME 4 (of 56) ]
[ time 144 ] Run JOB 0 at PRIORITY 0 [ TICKS 1 ALLOT 1 TIME 3 (of 56) ]
[ time 145 ] Run JOB 0 at PRIORITY 0 [ TICKS 0 ALLOT 1 TIME 2 (of 56) ]
[ time 146 ] Run JOB 0 at PRIORITY 0 [ TICKS 2 ALLOT 1 TIME 1 (of 56) ]
[ time 147 ] Run JOB 0 at PRIORITY 0 [ TICKS 1 ALLOT 1 TIME 0 (of 56) ]
[ time 148 ] FINISHED JOB 0
